Workbook
Name xGT: _xlfn.LAMBDA(_xlpm.bd,_xlpm.r,_xlpm.c,IF(OR(_xlpm.r<1,_xlpm.r>8,_xlpm.c<1,_xlpm.c>8),"##",INDEX(_xlpm.bd,_xlpm.r,_xlpm.c)))
Name xVAL: _xlfn.LAMBDA(_xlpm.pc,IF(OR(_xlpm.pc="",_xlpm.pc="##"),0,_xlfn.SWITCH(LEFT(_xlpm.pc,1),"p",100,"n",320,"b",330,"r",500,"q",900,"k",20000,0)))
Name xPN: _xlfn.LAMBDA(_xlpm.pc,_xlfn.SWITCH(LEFT(_xlpm.pc,1),"p","Pawn","n","Knight","b","Bishop","r","Rook","q","Queen","k","King",""))
Name xGLY: _xlfn.LAMBDA(_xlpm.pc,_xlfn.SWITCH(_xlpm.pc,"k1","♔","q1","♕","r1","♖","b1","♗","n1","♘","p1","♙","k2","♚","q2","♛","r2","♜","b2","♝","n2","♞","p2","♟",""))
Name xSQ: _xlfn.LAMBDA(_xlpm.r,_xlpm.c,CHAR(64+_xlpm.c)&_xlpm.r)
Name xATT: _xlfn.LAMBDA(_xlpm.bd,_xlpm.tr,_xlpm.tc,_xlpm.by,xMINA(_xlpm.bd,_xlpm.tr,_xlpm.tc,_xlpm.by)>0)
Name xKLOC: _xlfn.LAMBDA(_xlpm.bd,_xlpm.sd,MAX(_xlfn.MAKEARRAY(8,8,_xlfn.LAMBDA(_xlpm.r,_xlpm.c,IF(INDEX(_xlpm.bd,_xlpm.r,_xlpm.c)="k"&_xlpm.sd,_xlpm.r*10+_xlpm.c,0)))))

Sheet Sheet1
B1: =IF(UPPER(livegame!I5)="K1","♔", IF(UPPER(livegame!I5)="Q1","♕", IF(UPPER(livegame!I5)="R1","♖", IF(UPPER(livegame!I5)="B1","♗", IF(UPPER(livegame!I5)="N1","♘", IF(UPPER(livegame!I5)="P1","♙", IF(UPPER(livegame!I5)="K2","♚", IF(UPPER(livegame!I5)="Q2","♛", IF(UPPER(livegame!I5)="R2","♜", IF(UPPER(livegame!I5)="B2","♝", IF(UPPER(livegame!I5)="N2","♞", IF(UPPER(livegame!I5)="P2","♟","")))))))))))) -> ♖ | C1: =IF(UPPER(livegame!J5)="K1","♔", IF(UPPER(livegame!J5)="Q1","♕", IF(UPPER(livegame!J5)="R1","♖", IF(UPPER(livegame!J5)="B1","♗", IF(UPPER(livegame!J5)="N1","♘", IF(UPPER(livegame!J5)="P1","♙", IF(UPPER(livegame!J5)="K2","♚", IF(UPPER(livegame!J5)="Q2","♛", IF(UPPER(livegame!J5)="R2","♜", IF(UPPER(livegame!J5)="B2","♝", IF(UPPER(livegame!J5)="N2","♞", IF(UPPER(livegame!J5)="P2","♟","")))))))))))) -> ♘ | D1: =IF(UPPER(livegame!K5)="K1","♔", IF(UPPER(livegame!K5)="Q1","♕", IF(UPPER(livegame!K5)="R1","♖", IF(UPPER(livegame!K5)="B1","♗", IF(UPPER(livegame!K5)="N1","♘", IF(UPPER(livegame!K5)="P1","♙", IF(UPPER(livegame!K5)="K2","♚", IF(UPPER(livegame!K5)="Q2","♛", IF(UPPER(livegame!K5)="R2","♜", IF(UPPER(livegame!K5)="B2","♝", IF(UPPER(livegame!K5)="N2","♞", IF(UPPER(livegame!K5)="P2","♟","")))))))))))) -> ♗ | E1: =IF(UPPER(livegame!L5)="K1","♔", IF(UPPER(livegame!L5)="Q1","♕", IF(UPPER(livegame!L5)="R1","♖", IF(UPPER(livegame!L5)="B1","♗", IF(UPPER(livegame!L5)="N1","♘", IF(UPPER(livegame!L5)="P1","♙", IF(UPPER(livegame!L5)="K2","♚", IF(UPPER(livegame!L5)="Q2","♛", IF(UPPER(livegame!L5)="R2","♜", IF(UPPER(livegame!L5)="B2","♝", IF(UPPER(livegame!L5)="N2","♞", IF(UPPER(livegame!L5)="P2","♟","")))))))))))) -> ♔ | F1: =IF(UPPER(livegame!M5)="K1","♔", IF(UPPER(livegame!M5)="Q1","♕", IF(UPPER(livegame!M5)="R1","♖", IF(UPPER(livegame!M5)="B1","♗", IF(UPPER(livegame!M5)="N1","♘", IF(UPPER(livegame!M5)="P1","♙", IF(UPPER(livegame!M5)="K2","♚", IF(UPPER(livegame!M5)="Q2","♛", IF(UPPER(livegame!M5)="R2","♜", IF(UPPER(livegame!M5)="B2","♝", IF(UPPER(livegame!M5)="N2","♞", IF(UPPER(livegame!M5)="P2","♟","")))))))))))) -> ♕ | G1: =IF(UPPER(livegame!N5)="K1","♔", IF(UPPER(livegame!N5)="Q1","♕", IF(UPPER(livegame!N5)="R1","♖", IF(UPPER(livegame!N5)="B1","♗", IF(UPPER(livegame!N5)="N1","♘", IF(UPPER(livegame!N5)="P1","♙", IF(UPPER(livegame!N5)="K2","♚", IF(UPPER(livegame!N5)="Q2","♛", IF(UPPER(livegame!N5)="R2","♜", IF(UPPER(livegame!N5)="B2","♝", IF(UPPER(livegame!N5)="N2","♞", IF(UPPER(livegame!N5)="P2","♟","")))))))))))) -> ♗ | H1: =IF(UPPER(livegame!O5)="K1","♔", IF(UPPER(livegame!O5)="Q1","♕", IF(UPPER(livegame!O5)="R1","♖", IF(UPPER(livegame!O5)="B1","♗", IF(UPPER(livegame!O5)="N1","♘", IF(UPPER(livegame!O5)="P1","♙", IF(UPPER(livegame!O5)="K2","♚", IF(UPPER(livegame!O5)="Q2","♛", IF(UPPER(livegame!O5)="R2","♜", IF(UPPER(livegame!O5)="B2","♝", IF(UPPER(livegame!O5)="N2","♞", IF(UPPER(livegame!O5)="P2","♟","")))))))))))) -> ♘ | I1: =IF(UPPER(livegame!P5)="K1","♔", IF(UPPER(livegame!P5)="Q1","♕", IF(UPPER(livegame!P5)="R1","♖", IF(UPPER(livegame!P5)="B1","♗", IF(UPPER(livegame!P5)="N1","♘", IF(UPPER(livegame!P5)="P1","♙", IF(UPPER(livegame!P5)="K2","♚", IF(UPPER(livegame!P5)="Q2","♛", IF(UPPER(livegame!P5)="R2","♜", IF(UPPER(livegame!P5)="B2","♝", IF(UPPER(livegame!P5)="N2","♞", IF(UPPER(livegame!P5)="P2","♟","")))))))))))) -> ♖ | K1: =IF(livegame!S17<>"",livegame!S17,IF(AND(livegame!X23<>"",livegame!X23<>0),livegame!X23,IF(livegame!R16=1,"♔ WHITE TO MOVE","♚ BLACK TO MOVE")))
B2: =IF(UPPER(livegame!I6)="K1","♔", IF(UPPER(livegame!I6)="Q1","♕", IF(UPPER(livegame!I6)="R1","♖", IF(UPPER(livegame!I6)="B1","♗", IF(UPPER(livegame!I6)="N1","♘", IF(UPPER(livegame!I6)="P1","♙", IF(UPPER(livegame!I6)="K2","♚", IF(UPPER(livegame!I6)="Q2","♛", IF(UPPER(livegame!I6)="R2","♜", IF(UPPER(livegame!I6)="B2","♝", IF(UPPER(livegame!I6)="N2","♞", IF(UPPER(livegame!I6)="P2","♟","")))))))))))) -> ♙ | C2: =IF(UPPER(livegame!J6)="K1","♔", IF(UPPER(livegame!J6)="Q1","♕", IF(UPPER(livegame!J6)="R1","♖", IF(UPPER(livegame!J6)="B1","♗", IF(UPPER(livegame!J6)="N1","♘", IF(UPPER(livegame!J6)="P1","♙", IF(UPPER(livegame!J6)="K2","♚", IF(UPPER(livegame!J6)="Q2","♛", IF(UPPER(livegame!J6)="R2","♜", IF(UPPER(livegame!J6)="B2","♝", IF(UPPER(livegame!J6)="N2","♞", IF(UPPER(livegame!J6)="P2","♟","")))))))))))) -> ♙ | D2: =IF(UPPER(livegame!K6)="K1","♔", IF(UPPER(livegame!K6)="Q1","♕", IF(UPPER(livegame!K6)="R1","♖", IF(UPPER(livegame!K6)="B1","♗", IF(UPPER(livegame!K6)="N1","♘", IF(UPPER(livegame!K6)="P1","♙", IF(UPPER(livegame!K6)="K2","♚", IF(UPPER(livegame!K6)="Q2","♛", IF(UPPER(livegame!K6)="R2","♜", IF(UPPER(livegame!K6)="B2","♝", IF(UPPER(livegame!K6)="N2","♞", IF(UPPER(livegame!K6)="P2","♟","")))))))))))) -> ♙ | E2: =IF(UPPER(livegame!L6)="K1","♔", IF(UPPER(livegame!L6)="Q1","♕", IF(UPPER(livegame!L6)="R1","♖", IF(UPPER(livegame!L6)="B1","♗", IF(UPPER(livegame!L6)="N1","♘", IF(UPPER(livegame!L6)="P1","♙", IF(UPPER(livegame!L6)="K2","♚", IF(UPPER(livegame!L6)="Q2","♛", IF(UPPER(livegame!L6)="R2","♜", IF(UPPER(livegame!L6)="B2","♝", IF(UPPER(livegame!L6)="N2","♞", IF(UPPER(livegame!L6)="P2","♟","")))))))))))) -> ♙ | F2: =IF(UPPER(livegame!M6)="K1","♔", IF(UPPER(livegame!M6)="Q1","♕", IF(UPPER(livegame!M6)="R1","♖", IF(UPPER(livegame!M6)="B1","♗", IF(UPPER(livegame!M6)="N1","♘", IF(UPPER(livegame!M6)="P1","♙", IF(UPPER(livegame!M6)="K2","♚", IF(UPPER(livegame!M6)="Q2","♛", IF(UPPER(livegame!M6)="R2","♜", IF(UPPER(livegame!M6)="B2","♝", IF(UPPER(livegame!M6)="N2","♞", IF(UPPER(livegame!M6)="P2","♟","")))))))))))) -> ♙ | G2: =IF(UPPER(livegame!N6)="K1","♔", IF(UPPER(livegame!N6)="Q1","♕", IF(UPPER(livegame!N6)="R1","♖", IF(UPPER(livegame!N6)="B1","♗", IF(UPPER(livegame!N6)="N1","♘", IF(UPPER(livegame!N6)="P1","♙", IF(UPPER(livegame!N6)="K2","♚", IF(UPPER(livegame!N6)="Q2","♛", IF(UPPER(livegame!N6)="R2","♜", IF(UPPER(livegame!N6)="B2","♝", IF(UPPER(livegame!N6)="N2","♞", IF(UPPER(livegame!N6)="P2","♟","")))))))))))) -> ♙ | H2: =IF(UPPER(livegame!O6)="K1","♔", IF(UPPER(livegame!O6)="Q1","♕", IF(UPPER(livegame!O6)="R1","♖", IF(UPPER(livegame!O6)="B1","♗", IF(UPPER(livegame!O6)="N1","♘", IF(UPPER(livegame!O6)="P1","♙", IF(UPPER(livegame!O6)="K2","♚", IF(UPPER(livegame!O6)="Q2","♛", IF(UPPER(livegame!O6)="R2","♜", IF(UPPER(livegame!O6)="B2","♝", IF(UPPER(livegame!O6)="N2","♞", IF(UPPER(livegame!O6)="P2","♟","")))))))))))) -> ♙ | I2: =IF(UPPER(livegame!P6)="K1","♔", IF(UPPER(livegame!P6)="Q1","♕", IF(UPPER(livegame!P6)="R1","♖", IF(UPPER(livegame!P6)="B1","♗", IF(UPPER(livegame!P6)="N1","♘", IF(UPPER(livegame!P6)="P1","♙", IF(UPPER(livegame!P6)="K2","♚", IF(UPPER(livegame!P6)="Q2","♛", IF(UPPER(livegame!P6)="R2","♜", IF(UPPER(livegame!P6)="B2","♝", IF(UPPER(livegame!P6)="N2","♞", IF(UPPER(livegame!P6)="P2","♟","")))))))))))) -> ♙ | K2: TRUE | L2: =IF(K2,"Green to Play","Gray to Reset") -> Green to Play
B3: =IF(UPPER(livegame!I7)="K1","♔", IF(UPPER(livegame!I7)="Q1","♕", IF(UPPER(livegame!I7)="R1","♖", IF(UPPER(livegame!I7)="B1","♗", IF(UPPER(livegame!I7)="N1","♘", IF(UPPER(livegame!I7)="P1","♙", IF(UPPER(livegame!I7)="K2","♚", IF(UPPER(livegame!I7)="Q2","♛", IF(UPPER(livegame!I7)="R2","♜", IF(UPPER(livegame!I7)="B2","♝", IF(UPPER(livegame!I7)="N2","♞", IF(UPPER(livegame!I7)="P2","♟","")))))))))))) | C3: =IF(UPPER(livegame!J7)="K1","♔", IF(UPPER(livegame!J7)="Q1","♕", IF(UPPER(livegame!J7)="R1","♖", IF(UPPER(livegame!J7)="B1","♗", IF(UPPER(livegame!J7)="N1","♘", IF(UPPER(livegame!J7)="P1","♙", IF(UPPER(livegame!J7)="K2","♚", IF(UPPER(livegame!J7)="Q2","♛", IF(UPPER(livegame!J7)="R2","♜", IF(UPPER(livegame!J7)="B2","♝", IF(UPPER(livegame!J7)="N2","♞", IF(UPPER(livegame!J7)="P2","♟","")))))))))))) | D3: =IF(UPPER(livegame!K7)="K1","♔", IF(UPPER(livegame!K7)="Q1","♕", IF(UPPER(livegame!K7)="R1","♖", IF(UPPER(livegame!K7)="B1","♗", IF(UPPER(livegame!K7)="N1","♘", IF(UPPER(livegame!K7)="P1","♙", IF(UPPER(livegame!K7)="K2","♚", IF(UPPER(livegame!K7)="Q2","♛", IF(UPPER(livegame!K7)="R2","♜", IF(UPPER(livegame!K7)="B2","♝", IF(UPPER(livegame!K7)="N2","♞", IF(UPPER(livegame!K7)="P2","♟","")))))))))))) | E3: =IF(UPPER(livegame!L7)="K1","♔", IF(UPPER(livegame!L7)="Q1","♕", IF(UPPER(livegame!L7)="R1","♖", IF(UPPER(livegame!L7)="B1","♗", IF(UPPER(livegame!L7)="N1","♘", IF(UPPER(livegame!L7)="P1","♙", IF(UPPER(livegame!L7)="K2","♚", IF(UPPER(livegame!L7)="Q2","♛", IF(UPPER(livegame!L7)="R2","♜", IF(UPPER(livegame!L7)="B2","♝", IF(UPPER(livegame!L7)="N2","♞", IF(UPPER(livegame!L7)="P2","♟","")))))))))))) | F3: =IF(UPPER(livegame!M7)="K1","♔", IF(UPPER(livegame!M7)="Q1","♕", IF(UPPER(livegame!M7)="R1","♖", IF(UPPER(livegame!M7)="B1","♗", IF(UPPER(livegame!M7)="N1","♘", IF(UPPER(livegame!M7)="P1","♙", IF(UPPER(livegame!M7)="K2","♚", IF(UPPER(livegame!M7)="Q2","♛", IF(UPPER(livegame!M7)="R2","♜", IF(UPPER(livegame!M7)="B2","♝", IF(UPPER(livegame!M7)="N2","♞", IF(UPPER(livegame!M7)="P2","♟","")))))))))))) | G3: =IF(UPPER(livegame!N7)="K1","♔", IF(UPPER(livegame!N7)="Q1","♕", IF(UPPER(livegame!N7)="R1","♖", IF(UPPER(livegame!N7)="B1","♗", IF(UPPER(livegame!N7)="N1","♘", IF(UPPER(livegame!N7)="P1","♙", IF(UPPER(livegame!N7)="K2","♚", IF(UPPER(livegame!N7)="Q2","♛", IF(UPPER(livegame!N7)="R2","♜", IF(UPPER(livegame!N7)="B2","♝", IF(UPPER(livegame!N7)="N2","♞", IF(UPPER(livegame!N7)="P2","♟","")))))))))))) | H3: =IF(UPPER(livegame!O7)="K1","♔", IF(UPPER(livegame!O7)="Q1","♕", IF(UPPER(livegame!O7)="R1","♖", IF(UPPER(livegame!O7)="B1","♗", IF(UPPER(livegame!O7)="N1","♘", IF(UPPER(livegame!O7)="P1","♙", IF(UPPER(livegame!O7)="K2","♚", IF(UPPER(livegame!O7)="Q2","♛", IF(UPPER(livegame!O7)="R2","♜", IF(UPPER(livegame!O7)="B2","♝", IF(UPPER(livegame!O7)="N2","♞", IF(UPPER(livegame!O7)="P2","♟","")))))))))))) | I3: =IF(UPPER(livegame!P7)="K1","♔", IF(UPPER(livegame!P7)="Q1","♕", IF(UPPER(livegame!P7)="R1","♖", IF(UPPER(livegame!P7)="B1","♗", IF(UPPER(livegame!P7)="N1","♘", IF(UPPER(livegame!P7)="P1","♙", IF(UPPER(livegame!P7)="K2","♚", IF(UPPER(livegame!P7)="Q2","♛", IF(UPPER(livegame!P7)="R2","♜", IF(UPPER(livegame!P7)="B2","♝", IF(UPPER(livegame!P7)="N2","♞", IF(UPPER(livegame!P7)="P2","♟","")))))))))))) | K3: Tips: Blue indicates castling Eat the enemy king to win Todo: En Passant only at right times Pt. 1 of Caden's Microsoft Menagerie © 2026 Cifyr
B4: =IF(UPPER(livegame!I8)="K1","♔", IF(UPPER(livegame!I8)="Q1","♕", IF(UPPER(livegame!I8)="R1","♖", IF(UPPER(livegame!I8)="B1","♗", IF(UPPER(livegame!I8)="N1","♘", IF(UPPER(livegame!I8)="P1","♙", IF(UPPER(livegame!I8)="K2","♚", IF(UPPER(livegame!I8)="Q2","♛", IF(UPPER(livegame!I8)="R2","♜", IF(UPPER(livegame!I8)="B2","♝", IF(UPPER(livegame!I8)="N2","♞", IF(UPPER(livegame!I8)="P2","♟","")))))))))))) | C4: =IF(UPPER(livegame!J8)="K1","♔", IF(UPPER(livegame!J8)="Q1","♕", IF(UPPER(livegame!J8)="R1","♖", IF(UPPER(livegame!J8)="B1","♗", IF(UPPER(livegame!J8)="N1","♘", IF(UPPER(livegame!J8)="P1","♙", IF(UPPER(livegame!J8)="K2","♚", IF(UPPER(livegame!J8)="Q2","♛", IF(UPPER(livegame!J8)="R2","♜", IF(UPPER(livegame!J8)="B2","♝", IF(UPPER(livegame!J8)="N2","♞", IF(UPPER(livegame!J8)="P2","♟","")))))))))))) | D4: =IF(UPPER(livegame!K8)="K1","♔", IF(UPPER(livegame!K8)="Q1","♕", IF(UPPER(livegame!K8)="R1","♖", IF(UPPER(livegame!K8)="B1","♗", IF(UPPER(livegame!K8)="N1","♘", IF(UPPER(livegame!K8)="P1","♙", IF(UPPER(livegame!K8)="K2","♚", IF(UPPER(livegame!K8)="Q2","♛", IF(UPPER(livegame!K8)="R2","♜", IF(UPPER(livegame!K8)="B2","♝", IF(UPPER(livegame!K8)="N2","♞", IF(UPPER(livegame!K8)="P2","♟","")))))))))))) | E4: =IF(UPPER(livegame!L8)="K1","♔", IF(UPPER(livegame!L8)="Q1","♕", IF(UPPER(livegame!L8)="R1","♖", IF(UPPER(livegame!L8)="B1","♗", IF(UPPER(livegame!L8)="N1","♘", IF(UPPER(livegame!L8)="P1","♙", IF(UPPER(livegame!L8)="K2","♚", IF(UPPER(livegame!L8)="Q2","♛", IF(UPPER(livegame!L8)="R2","♜", IF(UPPER(livegame!L8)="B2","♝", IF(UPPER(livegame!L8)="N2","♞", IF(UPPER(livegame!L8)="P2","♟","")))))))))))) | F4: =IF(UPPER(livegame!M8)="K1","♔", IF(UPPER(livegame!M8)="Q1","♕", IF(UPPER(livegame!M8)="R1","♖", IF(UPPER(livegame!M8)="B1","♗", IF(UPPER(livegame!M8)="N1","♘", IF(UPPER(livegame!M8)="P1","♙", IF(UPPER(livegame!M8)="K2","♚", IF(UPPER(livegame!M8)="Q2","♛", IF(UPPER(livegame!M8)="R2","♜", IF(UPPER(livegame!M8)="B2","♝", IF(UPPER(livegame!M8)="N2","♞", IF(UPPER(livegame!M8)="P2","♟","")))))))))))) | G4: =IF(UPPER(livegame!N8)="K1","♔", IF(UPPER(livegame!N8)="Q1","♕", IF(UPPER(livegame!N8)="R1","♖", IF(UPPER(livegame!N8)="B1","♗", IF(UPPER(livegame!N8)="N1","♘", IF(UPPER(livegame!N8)="P1","♙", IF(UPPER(livegame!N8)="K2","♚", IF(UPPER(livegame!N8)="Q2","♛", IF(UPPER(livegame!N8)="R2","♜", IF(UPPER(livegame!N8)="B2","♝", IF(UPPER(livegame!N8)="N2","♞", IF(UPPER(livegame!N8)="P2","♟","")))))))))))) | H4: =IF(UPPER(livegame!O8)="K1","♔", IF(UPPER(livegame!O8)="Q1","♕", IF(UPPER(livegame!O8)="R1","♖", IF(UPPER(livegame!O8)="B1","♗", IF(UPPER(livegame!O8)="N1","♘", IF(UPPER(livegame!O8)="P1","♙", IF(UPPER(livegame!O8)="K2","♚", IF(UPPER(livegame!O8)="Q2","♛", IF(UPPER(livegame!O8)="R2","♜", IF(UPPER(livegame!O8)="B2","♝", IF(UPPER(livegame!O8)="N2","♞", IF(UPPER(livegame!O8)="P2","♟","")))))))))))) | I4: =IF(UPPER(livegame!P8)="K1","♔", IF(UPPER(livegame!P8)="Q1","♕", IF(UPPER(livegame!P8)="R1","♖", IF(UPPER(livegame!P8)="B1","♗", IF(UPPER(livegame!P8)="N1","♘", IF(UPPER(livegame!P8)="P1","♙", IF(UPPER(livegame!P8)="K2","♚", IF(UPPER(livegame!P8)="Q2","♛", IF(UPPER(livegame!P8)="R2","♜", IF(UPPER(livegame!P8)="B2","♝", IF(UPPER(livegame!P8)="N2","♞", IF(UPPER(livegame!P8)="P2","♟",""))))))))))))
B5: =IF(UPPER(livegame!I9)="K1","♔", IF(UPPER(livegame!I9)="Q1","♕", IF(UPPER(livegame!I9)="R1","♖", IF(UPPER(livegame!I9)="B1","♗", IF(UPPER(livegame!I9)="N1","♘", IF(UPPER(livegame!I9)="P1","♙", IF(UPPER(livegame!I9)="K2","♚", IF(UPPER(livegame!I9)="Q2","♛", IF(UPPER(livegame!I9)="R2","♜", IF(UPPER(livegame!I9)="B2","♝", IF(UPPER(livegame!I9)="N2","♞", IF(UPPER(livegame!I9)="P2","♟","")))))))))))) | C5: =IF(UPPER(livegame!J9)="K1","♔", IF(UPPER(livegame!J9)="Q1","♕", IF(UPPER(livegame!J9)="R1","♖", IF(UPPER(livegame!J9)="B1","♗", IF(UPPER(livegame!J9)="N1","♘", IF(UPPER(livegame!J9)="P1","♙", IF(UPPER(livegame!J9)="K2","♚", IF(UPPER(livegame!J9)="Q2","♛", IF(UPPER(livegame!J9)="R2","♜", IF(UPPER(livegame!J9)="B2","♝", IF(UPPER(livegame!J9)="N2","♞", IF(UPPER(livegame!J9)="P2","♟","")))))))))))) | D5: =IF(UPPER(livegame!K9)="K1","♔", IF(UPPER(livegame!K9)="Q1","♕", IF(UPPER(livegame!K9)="R1","♖", IF(UPPER(livegame!K9)="B1","♗", IF(UPPER(livegame!K9)="N1","♘", IF(UPPER(livegame!K9)="P1","♙", IF(UPPER(livegame!K9)="K2","♚", IF(UPPER(livegame!K9)="Q2","♛", IF(UPPER(livegame!K9)="R2","♜", IF(UPPER(livegame!K9)="B2","♝", IF(UPPER(livegame!K9)="N2","♞", IF(UPPER(livegame!K9)="P2","♟","")))))))))))) | E5: =IF(UPPER(livegame!L9)="K1","♔", IF(UPPER(livegame!L9)="Q1","♕", IF(UPPER(livegame!L9)="R1","♖", IF(UPPER(livegame!L9)="B1","♗", IF(UPPER(livegame!L9)="N1","♘", IF(UPPER(livegame!L9)="P1","♙", IF(UPPER(livegame!L9)="K2","♚", IF(UPPER(livegame!L9)="Q2","♛", IF(UPPER(livegame!L9)="R2","♜", IF(UPPER(livegame!L9)="B2","♝", IF(UPPER(livegame!L9)="N2","♞", IF(UPPER(livegame!L9)="P2","♟","")))))))))))) | F5: =IF(UPPER(livegame!M9)="K1","♔", IF(UPPER(livegame!M9)="Q1","♕", IF(UPPER(livegame!M9)="R1","♖", IF(UPPER(livegame!M9)="B1","♗", IF(UPPER(livegame!M9)="N1","♘", IF(UPPER(livegame!M9)="P1","♙", IF(UPPER(livegame!M9)="K2","♚", IF(UPPER(livegame!M9)="Q2","♛", IF(UPPER(livegame!M9)="R2","♜", IF(UPPER(livegame!M9)="B2","♝", IF(UPPER(livegame!M9)="N2","♞", IF(UPPER(livegame!M9)="P2","♟","")))))))))))) | G5: =IF(UPPER(livegame!N9)="K1","♔", IF(UPPER(livegame!N9)="Q1","♕", IF(UPPER(livegame!N9)="R1","♖", IF(UPPER(livegame!N9)="B1","♗", IF(UPPER(livegame!N9)="N1","♘", IF(UPPER(livegame!N9)="P1","♙", IF(UPPER(livegame!N9)="K2","♚", IF(UPPER(livegame!N9)="Q2","♛", IF(UPPER(livegame!N9)="R2","♜", IF(UPPER(livegame!N9)="B2","♝", IF(UPPER(livegame!N9)="N2","♞", IF(UPPER(livegame!N9)="P2","♟","")))))))))))) | H5: =IF(UPPER(livegame!O9)="K1","♔", IF(UPPER(livegame!O9)="Q1","♕", IF(UPPER(livegame!O9)="R1","♖", IF(UPPER(livegame!O9)="B1","♗", IF(UPPER(livegame!O9)="N1","♘", IF(UPPER(livegame!O9)="P1","♙", IF(UPPER(livegame!O9)="K2","♚", IF(UPPER(livegame!O9)="Q2","♛", IF(UPPER(livegame!O9)="R2","♜", IF(UPPER(livegame!O9)="B2","♝", IF(UPPER(livegame!O9)="N2","♞", IF(UPPER(livegame!O9)="P2","♟","")))))))))))) | I5: =IF(UPPER(livegame!P9)="K1","♔", IF(UPPER(livegame!P9)="Q1","♕", IF(UPPER(livegame!P9)="R1","♖", IF(UPPER(livegame!P9)="B1","♗", IF(UPPER(livegame!P9)="N1","♘", IF(UPPER(livegame!P9)="P1","♙", IF(UPPER(livegame!P9)="K2","♚", IF(UPPER(livegame!P9)="Q2","♛", IF(UPPER(livegame!P9)="R2","♜", IF(UPPER(livegame!P9)="B2","♝", IF(UPPER(livegame!P9)="N2","♞", IF(UPPER(livegame!P9)="P2","♟","")))))))))))) | Q5: =K2 -> TRUE | R5: started
B6: =IF(UPPER(livegame!I10)="K1","♔", IF(UPPER(livegame!I10)="Q1","♕", IF(UPPER(livegame!I10)="R1","♖", IF(UPPER(livegame!I10)="B1","♗", IF(UPPER(livegame!I10)="N1","♘", IF(UPPER(livegame!I10)="P1","♙", IF(UPPER(livegame!I10)="K2","♚", IF(UPPER(livegame!I10)="Q2","♛", IF(UPPER(livegame!I10)="R2","♜", IF(UPPER(livegame!I10)="B2","♝", IF(UPPER(livegame!I10)="N2","♞", IF(UPPER(livegame!I10)="P2","♟","")))))))))))) | C6: =IF(UPPER(livegame!J10)="K1","♔", IF(UPPER(livegame!J10)="Q1","♕", IF(UPPER(livegame!J10)="R1","♖", IF(UPPER(livegame!J10)="B1","♗", IF(UPPER(livegame!J10)="N1","♘", IF(UPPER(livegame!J10)="P1","♙", IF(UPPER(livegame!J10)="K2","♚", IF(UPPER(livegame!J10)="Q2","♛", IF(UPPER(livegame!J10)="R2","♜", IF(UPPER(livegame!J10)="B2","♝", IF(UPPER(livegame!J10)="N2","♞", IF(UPPER(livegame!J10)="P2","♟","")))))))))))) | D6: =IF(UPPER(livegame!K10)="K1","♔", IF(UPPER(livegame!K10)="Q1","♕", IF(UPPER(livegame!K10)="R1","♖", IF(UPPER(livegame!K10)="B1","♗", IF(UPPER(livegame!K10)="N1","♘", IF(UPPER(livegame!K10)="P1","♙", IF(UPPER(livegame!K10)="K2","♚", IF(UPPER(livegame!K10)="Q2","♛", IF(UPPER(livegame!K10)="R2","♜", IF(UPPER(livegame!K10)="B2","♝", IF(UPPER(livegame!K10)="N2","♞", IF(UPPER(livegame!K10)="P2","♟","")))))))))))) | E6: =IF(UPPER(livegame!L10)="K1","♔", IF(UPPER(livegame!L10)="Q1","♕", IF(UPPER(livegame!L10)="R1","♖", IF(UPPER(livegame!L10)="B1","♗", IF(UPPER(livegame!L10)="N1","♘", IF(UPPER(livegame!L10)="P1","♙", IF(UPPER(livegame!L10)="K2","♚", IF(UPPER(livegame!L10)="Q2","♛", IF(UPPER(livegame!L10)="R2","♜", IF(UPPER(livegame!L10)="B2","♝", IF(UPPER(livegame!L10)="N2","♞", IF(UPPER(livegame!L10)="P2","♟","")))))))))))) | F6: =IF(UPPER(livegame!M10)="K1","♔", IF(UPPER(livegame!M10)="Q1","♕", IF(UPPER(livegame!M10)="R1","♖", IF(UPPER(livegame!M10)="B1","♗", IF(UPPER(livegame!M10)="N1","♘", IF(UPPER(livegame!M10)="P1","♙", IF(UPPER(livegame!M10)="K2","♚", IF(UPPER(livegame!M10)="Q2","♛", IF(UPPER(livegame!M10)="R2","♜", IF(UPPER(livegame!M10)="B2","♝", IF(UPPER(livegame!M10)="N2","♞", IF(UPPER(livegame!M10)="P2","♟","")))))))))))) | G6: =IF(UPPER(livegame!N10)="K1","♔", IF(UPPER(livegame!N10)="Q1","♕", IF(UPPER(livegame!N10)="R1","♖", IF(UPPER(livegame!N10)="B1","♗", IF(UPPER(livegame!N10)="N1","♘", IF(UPPER(livegame!N10)="P1","♙", IF(UPPER(livegame!N10)="K2","♚", IF(UPPER(livegame!N10)="Q2","♛", IF(UPPER(livegame!N10)="R2","♜", IF(UPPER(livegame!N10)="B2","♝", IF(UPPER(livegame!N10)="N2","♞", IF(UPPER(livegame!N10)="P2","♟","")))))))))))) | H6: =IF(UPPER(livegame!O10)="K1","♔", IF(UPPER(livegame!O10)="Q1","♕", IF(UPPER(livegame!O10)="R1","♖", IF(UPPER(livegame!O10)="B1","♗", IF(UPPER(livegame!O10)="N1","♘", IF(UPPER(livegame!O10)="P1","♙", IF(UPPER(livegame!O10)="K2","♚", IF(UPPER(livegame!O10)="Q2","♛", IF(UPPER(livegame!O10)="R2","♜", IF(UPPER(livegame!O10)="B2","♝", IF(UPPER(livegame!O10)="N2","♞", IF(UPPER(livegame!O10)="P2","♟","")))))))))))) | I6: =IF(UPPER(livegame!P10)="K1","♔", IF(UPPER(livegame!P10)="Q1","♕", IF(UPPER(livegame!P10)="R1","♖", IF(UPPER(livegame!P10)="B1","♗", IF(UPPER(livegame!P10)="N1","♘", IF(UPPER(livegame!P10)="P1","♙", IF(UPPER(livegame!P10)="K2","♚", IF(UPPER(livegame!P10)="Q2","♛", IF(UPPER(livegame!P10)="R2","♜", IF(UPPER(livegame!P10)="B2","♝", IF(UPPER(livegame!P10)="N2","♞", IF(UPPER(livegame!P10)="P2","♟","")))))))))))) | Q6: =livegame!S17
B7: =IF(UPPER(livegame!I11)="K1","♔", IF(UPPER(livegame!I11)="Q1","♕", IF(UPPER(livegame!I11)="R1","♖", IF(UPPER(livegame!I11)="B1","♗", IF(UPPER(livegame!I11)="N1","♘", IF(UPPER(livegame!I11)="P1","♙", IF(UPPER(livegame!I11)="K2","♚", IF(UPPER(livegame!I11)="Q2","♛", IF(UPPER(livegame!I11)="R2","♜", IF(UPPER(livegame!I11)="B2","♝", IF(UPPER(livegame!I11)="N2","♞", IF(UPPER(livegame!I11)="P2","♟","")))))))))))) -> ♟ | C7: =IF(UPPER(livegame!J11)="K1","♔", IF(UPPER(livegame!J11)="Q1","♕", IF(UPPER(livegame!J11)="R1","♖", IF(UPPER(livegame!J11)="B1","♗", IF(UPPER(livegame!J11)="N1","♘", IF(UPPER(livegame!J11)="P1","♙", IF(UPPER(livegame!J11)="K2","♚", IF(UPPER(livegame!J11)="Q2","♛", IF(UPPER(livegame!J11)="R2","♜", IF(UPPER(livegame!J11)="B2","♝", IF(UPPER(livegame!J11)="N2","♞", IF(UPPER(livegame!J11)="P2","♟","")))))))))))) -> ♟ | D7: =IF(UPPER(livegame!K11)="K1","♔", IF(UPPER(livegame!K11)="Q1","♕", IF(UPPER(livegame!K11)="R1","♖", IF(UPPER(livegame!K11)="B1","♗", IF(UPPER(livegame!K11)="N1","♘", IF(UPPER(livegame!K11)="P1","♙", IF(UPPER(livegame!K11)="K2","♚", IF(UPPER(livegame!K11)="Q2","♛", IF(UPPER(livegame!K11)="R2","♜", IF(UPPER(livegame!K11)="B2","♝", IF(UPPER(livegame!K11)="N2","♞", IF(UPPER(livegame!K11)="P2","♟","")))))))))))) -> ♟ | E7: =IF(UPPER(livegame!L11)="K1","♔", IF(UPPER(livegame!L11)="Q1","♕", IF(UPPER(livegame!L11)="R1","♖", IF(UPPER(livegame!L11)="B1","♗", IF(UPPER(livegame!L11)="N1","♘", IF(UPPER(livegame!L11)="P1","♙", IF(UPPER(livegame!L11)="K2","♚", IF(UPPER(livegame!L11)="Q2","♛", IF(UPPER(livegame!L11)="R2","♜", IF(UPPER(livegame!L11)="B2","♝", IF(UPPER(livegame!L11)="N2","♞", IF(UPPER(livegame!L11)="P2","♟","")))))))))))) -> ♟ | F7: =IF(UPPER(livegame!M11)="K1","♔", IF(UPPER(livegame!M11)="Q1","♕", IF(UPPER(livegame!M11)="R1","♖", IF(UPPER(livegame!M11)="B1","♗", IF(UPPER(livegame!M11)="N1","♘", IF(UPPER(livegame!M11)="P1","♙", IF(UPPER(livegame!M11)="K2","♚", IF(UPPER(livegame!M11)="Q2","♛", IF(UPPER(livegame!M11)="R2","♜", IF(UPPER(livegame!M11)="B2","♝", IF(UPPER(livegame!M11)="N2","♞", IF(UPPER(livegame!M11)="P2","♟","")))))))))))) -> ♟ | G7: =IF(UPPER(livegame!N11)="K1","♔", IF(UPPER(livegame!N11)="Q1","♕", IF(UPPER(livegame!N11)="R1","♖", IF(UPPER(livegame!N11)="B1","♗", IF(UPPER(livegame!N11)="N1","♘", IF(UPPER(livegame!N11)="P1","♙", IF(UPPER(livegame!N11)="K2","♚", IF(UPPER(livegame!N11)="Q2","♛", IF(UPPER(livegame!N11)="R2","♜", IF(UPPER(livegame!N11)="B2","♝", IF(UPPER(livegame!N11)="N2","♞", IF(UPPER(livegame!N11)="P2","♟","")))))))))))) -> ♟ | H7: =IF(UPPER(livegame!O11)="K1","♔", IF(UPPER(livegame!O11)="Q1","♕", IF(UPPER(livegame!O11)="R1","♖", IF(UPPER(livegame!O11)="B1","♗", IF(UPPER(livegame!O11)="N1","♘", IF(UPPER(livegame!O11)="P1","♙", IF(UPPER(livegame!O11)="K2","♚", IF(UPPER(livegame!O11)="Q2","♛", IF(UPPER(livegame!O11)="R2","♜", IF(UPPER(livegame!O11)="B2","♝", IF(UPPER(livegame!O11)="N2","♞", IF(UPPER(livegame!O11)="P2","♟","")))))))))))) -> ♟ | I7: =IF(UPPER(livegame!P11)="K1","♔", IF(UPPER(livegame!P11)="Q1","♕", IF(UPPER(livegame!P11)="R1","♖", IF(UPPER(livegame!P11)="B1","♗", IF(UPPER(livegame!P11)="N1","♘", IF(UPPER(livegame!P11)="P1","♙", IF(UPPER(livegame!P11)="K2","♚", IF(UPPER(livegame!P11)="Q2","♛", IF(UPPER(livegame!P11)="R2","♜", IF(UPPER(livegame!P11)="B2","♝", IF(UPPER(livegame!P11)="N2","♞", IF(UPPER(livegame!P11)="P2","♟","")))))))))))) -> ♟
B8: =IF(UPPER(livegame!I12)="K1","♔", IF(UPPER(livegame!I12)="Q1","♕", IF(UPPER(livegame!I12)="R1","♖", IF(UPPER(livegame!I12)="B1","♗", IF(UPPER(livegame!I12)="N1","♘", IF(UPPER(livegame!I12)="P1","♙", IF(UPPER(livegame!I12)="K2","♚", IF(UPPER(livegame!I12)="Q2","♛", IF(UPPER(livegame!I12)="R2","♜", IF(UPPER(livegame!I12)="B2","♝", IF(UPPER(livegame!I12)="N2","♞", IF(UPPER(livegame!I12)="P2","♟","")))))))))))) -> ♜ | C8: =IF(UPPER(livegame!J12)="K1","♔", IF(UPPER(livegame!J12)="Q1","♕", IF(UPPER(livegame!J12)="R1","♖", IF(UPPER(livegame!J12)="B1","♗", IF(UPPER(livegame!J12)="N1","♘", IF(UPPER(livegame!J12)="P1","♙", IF(UPPER(livegame!J12)="K2","♚", IF(UPPER(livegame!J12)="Q2","♛", IF(UPPER(livegame!J12)="R2","♜", IF(UPPER(livegame!J12)="B2","♝", IF(UPPER(livegame!J12)="N2","♞", IF(UPPER(livegame!J12)="P2","♟","")))))))))))) -> ♞ | D8: =IF(UPPER(livegame!K12)="K1","♔", IF(UPPER(livegame!K12)="Q1","♕", IF(UPPER(livegame!K12)="R1","♖", IF(UPPER(livegame!K12)="B1","♗", IF(UPPER(livegame!K12)="N1","♘", IF(UPPER(livegame!K12)="P1","♙", IF(UPPER(livegame!K12)="K2","♚", IF(UPPER(livegame!K12)="Q2","♛", IF(UPPER(livegame!K12)="R2","♜", IF(UPPER(livegame!K12)="B2","♝", IF(UPPER(livegame!K12)="N2","♞", IF(UPPER(livegame!K12)="P2","♟","")))))))))))) -> ♝ | E8: =IF(UPPER(livegame!L12)="K1","♔", IF(UPPER(livegame!L12)="Q1","♕", IF(UPPER(livegame!L12)="R1","♖", IF(UPPER(livegame!L12)="B1","♗", IF(UPPER(livegame!L12)="N1","♘", IF(UPPER(livegame!L12)="P1","♙", IF(UPPER(livegame!L12)="K2","♚", IF(UPPER(livegame!L12)="Q2","♛", IF(UPPER(livegame!L12)="R2","♜", IF(UPPER(livegame!L12)="B2","♝", IF(UPPER(livegame!L12)="N2","♞", IF(UPPER(livegame!L12)="P2","♟","")))))))))))) -> ♚ | F8: =IF(UPPER(livegame!M12)="K1","♔", IF(UPPER(livegame!M12)="Q1","♕", IF(UPPER(livegame!M12)="R1","♖", IF(UPPER(livegame!M12)="B1","♗", IF(UPPER(livegame!M12)="N1","♘", IF(UPPER(livegame!M12)="P1","♙", IF(UPPER(livegame!M12)="K2","♚", IF(UPPER(livegame!M12)="Q2","♛", IF(UPPER(livegame!M12)="R2","♜", IF(UPPER(livegame!M12)="B2","♝", IF(UPPER(livegame!M12)="N2","♞", IF(UPPER(livegame!M12)="P2","♟","")))))))))))) -> ♛ | G8: =IF(UPPER(livegame!N12)="K1","♔", IF(UPPER(livegame!N12)="Q1","♕", IF(UPPER(livegame!N12)="R1","♖", IF(UPPER(livegame!N12)="B1","♗", IF(UPPER(livegame!N12)="N1","♘", IF(UPPER(livegame!N12)="P1","♙", IF(UPPER(livegame!N12)="K2","♚", IF(UPPER(livegame!N12)="Q2","♛", IF(UPPER(livegame!N12)="R2","♜", IF(UPPER(livegame!N12)="B2","♝", IF(UPPER(livegame!N12)="N2","♞", IF(UPPER(livegame!N12)="P2","♟","")))))))))))) -> ♝ | H8: =IF(UPPER(livegame!O12)="K1","♔", IF(UPPER(livegame!O12)="Q1","♕", IF(UPPER(livegame!O12)="R1","♖", IF(UPPER(livegame!O12)="B1","♗", IF(UPPER(livegame!O12)="N1","♘", IF(UPPER(livegame!O12)="P1","♙", IF(UPPER(livegame!O12)="K2","♚", IF(UPPER(livegame!O12)="Q2","♛", IF(UPPER(livegame!O12)="R2","♜", IF(UPPER(livegame!O12)="B2","♝", IF(UPPER(livegame!O12)="N2","♞", IF(UPPER(livegame!O12)="P2","♟","")))))))))))) -> ♞ | I8: =IF(UPPER(livegame!P12)="K1","♔", IF(UPPER(livegame!P12)="Q1","♕", IF(UPPER(livegame!P12)="R1","♖", IF(UPPER(livegame!P12)="B1","♗", IF(UPPER(livegame!P12)="N1","♘", IF(UPPER(livegame!P12)="P1","♙", IF(UPPER(livegame!P12)="K2","♚", IF(UPPER(livegame!P12)="Q2","♛", IF(UPPER(livegame!P12)="R2","♜", IF(UPPER(livegame!P12)="B2","♝", IF(UPPER(livegame!P12)="N2","♞", IF(UPPER(livegame!P12)="P2","♟","")))))))))))) -> ♜

Sheet Coach
B1: CHESS COACH
B2: Best-move suggestions, recalculated from the live board.
B4: =IF(Engine!$L$1=1,"♔ WHITE TO MOVE","♚ BLACK TO MOVE")
B5: =IF(livegame!S17<>"",livegame!S17,IF(AND(livegame!X23<>"",livegame!X23<>0),livegame!X23,"Game in progress"))
B7: BEST MOVE
B8: =IF(Engine!$C$21="","No move available",Engine!$F$21&" "&Engine!$C$21&" to "&Engine!$D$21) | E8: =IF(Engine!$C$21="","",IF(Engine!$H$21="Checkmate","M1",IF(Engine!$H$21="Stalemate","draw",TEXT(Engine!$G$21,"+0.00;-0.00;0.00")))) | F8: =IF(Engine!$C$21="","",Engine!$I$21)
B10: # | C10: Move | D10: Piece | E10: Eval | F10: Type | G10: Why this move
B11: 1 | C11: =IF(Engine!$C$21="","",Engine!$C$21&" to "&Engine!$D$21) | D11: =IF(Engine!$C$21="","",Engine!$F$21&" "&Engine!$E$21) | E11: =IF(Engine!$C$21="","",IF(Engine!$H$21="Checkmate","M1",IF(Engine!$H$21="Stalemate","draw",TEXT(Engine!$G$21,"+0.00;-0.00;0.00")))) | F11: =IF(Engine!$C$21="","",Engine!$H$21) | G11: =IF(Engine!$C$21="","",Engine!$I$21)
B12: 2 | C12: =IF(Engine!$C$22="","",Engine!$C$22&" to "&Engine!$D$22) | D12: =IF(Engine!$C$22="","",Engine!$F$22&" "&Engine!$E$22) | E12: =IF(Engine!$C$22="","",IF(Engine!$H$22="Checkmate","M1",IF(Engine!$H$22="Stalemate","draw",TEXT(Engine!$G$22,"+0.00;-0.00;0.00")))) | F12: =IF(Engine!$C$22="","",Engine!$H$22) | G12: =IF(Engine!$C$22="","",Engine!$I$22)
B13: 3 | C13: =IF(Engine!$C$23="","",Engine!$C$23&" to "&Engine!$D$23) | D13: =IF(Engine!$C$23="","",Engine!$F$23&" "&Engine!$E$23) | E13: =IF(Engine!$C$23="","",IF(Engine!$H$23="Checkmate","M1",IF(Engine!$H$23="Stalemate","draw",TEXT(Engine!$G$23,"+0.00;-0.00;0.00")))) | F13: =IF(Engine!$C$23="","",Engine!$H$23) | G13: =IF(Engine!$C$23="","",Engine!$I$23)
B14: 4 | C14: =IF(Engine!$C$24="","",Engine!$C$24&" to "&Engine!$D$24) | D14: =IF(Engine!$C$24="","",Engine!$F$24&" "&Engine!$E$24) | E14: =IF(Engine!$C$24="","",IF(Engine!$H$24="Checkmate","M1",IF(Engine!$H$24="Stalemate","draw",TEXT(Engine!$G$24,"+0.00;-0.00;0.00")))) | F14: =IF(Engine!$C$24="","",Engine!$H$24) | G14: =IF(Engine!$C$24="","",Engine!$I$24)
B15: 5 | C15: =IF(Engine!$C$25="","",Engine!$C$25&" to "&Engine!$D$25) | D15: =IF(Engine!$C$25="","",Engine!$F$25&" "&Engine!$E$25) | E15: =IF(Engine!$C$25="","",IF(Engine!$H$25="Checkmate","M1",IF(Engine!$H$25="Stalemate","draw",TEXT(Engine!$G$25,"+0.00;-0.00;0.00")))) | F15: =IF(Engine!$C$25="","",Engine!$H$25) | G15: =IF(Engine!$C$25="","",Engine!$I$25)
B16: 6 | C16: =IF(Engine!$C$26="","",Engine!$C$26&" to "&Engine!$D$26) | D16: =IF(Engine!$C$26="","",Engine!$F$26&" "&Engine!$E$26) | E16: =IF(Engine!$C$26="","",IF(Engine!$H$26="Checkmate","M1",IF(Engine!$H$26="Stalemate","draw",TEXT(Engine!$G$26,"+0.00;-0.00;0.00")))) | F16: =IF(Engine!$C$26="","",Engine!$H$26) | G16: =IF(Engine!$C$26="","",Engine!$I$26)
B18: Engine | C18: ON | D18: set to OFF if the board feels slow
B19: Candidates | C19: 8 | D19: moves taken to the 2-ply stage
B20: Engine plays | C20: OFF | D20: engine answers your moves automatically
B21: Eval is in pawns for the side to move: +1.00 means that side is a pawn up, M1 is mate in one. Stage 1 scores every legal move on material, piece placement and whether the landing square is defended; stage 2 answers the best few with the opponent's whole legal reply list and keeps the worst outcome. Engine plays makes it answer your moves by itself, driving the same squares you would click, so captures, promotion and the turn indicator all behave normally; set it to OFF for two-player. Autoplay uses the stage 1 score and takes a few seconds a move. Castling and en passant are not generated, and forks that pay off two moves later are past the horizon.

Sheet piecetype
A1: =IF(RIGHT(livegame!I5)="0","",RIGHT(livegame!I5)) -> 1 | B1: =IF(RIGHT(livegame!J5)="0","",RIGHT(livegame!J5)) -> 1 | C1: =IF(RIGHT(livegame!K5)="0","",RIGHT(livegame!K5)) -> 1 | D1: =IF(RIGHT(livegame!L5)="0","",RIGHT(livegame!L5)) -> 1 | E1: =IF(RIGHT(livegame!M5)="0","",RIGHT(livegame!M5)) -> 1 | F1: =IF(RIGHT(livegame!N5)="0","",RIGHT(livegame!N5)) -> 1 | G1: =IF(RIGHT(livegame!O5)="0","",RIGHT(livegame!O5)) -> 1 | H1: =IF(RIGHT(livegame!P5)="0","",RIGHT(livegame!P5)) -> 1
A2: =IF(RIGHT(livegame!I6)="0","",RIGHT(livegame!I6)) -> 1 | B2: =IF(RIGHT(livegame!J6)="0","",RIGHT(livegame!J6)) -> 1 | C2: =IF(RIGHT(livegame!K6)="0","",RIGHT(livegame!K6)) -> 1 | D2: =IF(RIGHT(livegame!L6)="0","",RIGHT(livegame!L6)) -> 1 | E2: =IF(RIGHT(livegame!M6)="0","",RIGHT(livegame!M6)) -> 1 | F2: =IF(RIGHT(livegame!N6)="0","",RIGHT(livegame!N6)) -> 1 | G2: =IF(RIGHT(livegame!O6)="0","",RIGHT(livegame!O6)) -> 1 | H2: =IF(RIGHT(livegame!P6)="0","",RIGHT(livegame!P6)) -> 1
A3: =IF(RIGHT(livegame!I7)="0","",RIGHT(livegame!I7)) | B3: =IF(RIGHT(livegame!J7)="0","",RIGHT(livegame!J7)) | C3: =IF(RIGHT(livegame!K7)="0","",RIGHT(livegame!K7)) | D3: =IF(RIGHT(livegame!L7)="0","",RIGHT(livegame!L7)) | E3: =IF(RIGHT(livegame!M7)="0","",RIGHT(livegame!M7)) | F3: =IF(RIGHT(livegame!N7)="0","",RIGHT(livegame!N7)) | G3: =IF(RIGHT(livegame!O7)="0","",RIGHT(livegame!O7)) | H3: =IF(RIGHT(livegame!P7)="0","",RIGHT(livegame!P7))
A4: =IF(RIGHT(livegame!I8)="0","",RIGHT(livegame!I8)) | B4: =IF(RIGHT(livegame!J8)="0","",RIGHT(livegame!J8)) | C4: =IF(RIGHT(livegame!K8)="0","",RIGHT(livegame!K8)) | D4: =IF(RIGHT(livegame!L8)="0","",RIGHT(livegame!L8)) | E4: =IF(RIGHT(livegame!M8)="0","",RIGHT(livegame!M8)) | F4: =IF(RIGHT(livegame!N8)="0","",RIGHT(livegame!N8)) | G4: =IF(RIGHT(livegame!O8)="0","",RIGHT(livegame!O8)) | H4: =IF(RIGHT(livegame!P8)="0","",RIGHT(livegame!P8))
A5: =IF(RIGHT(livegame!I9)="0","",RIGHT(livegame!I9)) | B5: =IF(RIGHT(livegame!J9)="0","",RIGHT(livegame!J9)) | C5: =IF(RIGHT(livegame!K9)="0","",RIGHT(livegame!K9)) | D5: =IF(RIGHT(livegame!L9)="0","",RIGHT(livegame!L9)) | E5: =IF(RIGHT(livegame!M9)="0","",RIGHT(livegame!M9)) | F5: =IF(RIGHT(livegame!N9)="0","",RIGHT(livegame!N9)) | G5: =IF(RIGHT(livegame!O9)="0","",RIGHT(livegame!O9)) | H5: =IF(RIGHT(livegame!P9)="0","",RIGHT(livegame!P9))
A6: =IF(RIGHT(livegame!I10)="0","",RIGHT(livegame!I10)) | B6: =IF(RIGHT(livegame!J10)="0","",RIGHT(livegame!J10)) | C6: =IF(RIGHT(livegame!K10)="0","",RIGHT(livegame!K10)) | D6: =IF(RIGHT(livegame!L10)="0","",RIGHT(livegame!L10)) | E6: =IF(RIGHT(livegame!M10)="0","",RIGHT(livegame!M10)) | F6: =IF(RIGHT(livegame!N10)="0","",RIGHT(livegame!N10)) | G6: =IF(RIGHT(livegame!O10)="0","",RIGHT(livegame!O10)) | H6: =IF(RIGHT(livegame!P10)="0","",RIGHT(livegame!P10))
A7: =IF(RIGHT(livegame!I11)="0","",RIGHT(livegame!I11)) -> 2 | B7: =IF(RIGHT(livegame!J11)="0","",RIGHT(livegame!J11)) -> 2 | C7: =IF(RIGHT(livegame!K11)="0","",RIGHT(livegame!K11)) -> 2 | D7: =IF(RIGHT(livegame!L11)="0","",RIGHT(livegame!L11)) -> 2 | E7: =IF(RIGHT(livegame!M11)="0","",RIGHT(livegame!M11)) -> 2 | F7: =IF(RIGHT(livegame!N11)="0","",RIGHT(livegame!N11)) -> 2 | G7: =IF(RIGHT(livegame!O11)="0","",RIGHT(livegame!O11)) -> 2 | H7: =IF(RIGHT(livegame!P11)="0","",RIGHT(livegame!P11)) -> 2
A8: =IF(RIGHT(livegame!I12)="0","",RIGHT(livegame!I12)) -> 2 | B8: =IF(RIGHT(livegame!J12)="0","",RIGHT(livegame!J12)) -> 2 | C8: =IF(RIGHT(livegame!K12)="0","",RIGHT(livegame!K12)) -> 2 | D8: =IF(RIGHT(livegame!L12)="0","",RIGHT(livegame!L12)) -> 2 | E8: =IF(RIGHT(livegame!M12)="0","",RIGHT(livegame!M12)) -> 2 | F8: =IF(RIGHT(livegame!N12)="0","",RIGHT(livegame!N12)) -> 2 | G8: =IF(RIGHT(livegame!O12)="0","",RIGHT(livegame!O12)) -> 2 | H8: =IF(RIGHT(livegame!P12)="0","",RIGHT(livegame!P12)) -> 2

Sheet input handling
A1: TRUE | B1: FALSE | C1: TRUE | D1: TRUE | E1: FALSE | F1: TRUE | G1: TRUE | H1: FALSE
A2: TRUE | B2: FALSE | C2: FALSE | D2: TRUE | E2: FALSE | F2: FALSE | G2: FALSE | H2: TRUE
A3: TRUE | B3: FALSE | C3: TRUE | D3: FALSE | E3: TRUE | F3: TRUE | G3: FALSE | H3: TRUE
A4: TRUE | B4: FALSE | C4: FALSE | D4: TRUE | E4: FALSE | F4: TRUE | G4: TRUE | H4: TRUE
A5: TRUE | B5: FALSE | C5: FALSE | D5: TRUE | E5: FALSE | F5: FALSE | G5: FALSE | H5: TRUE
A6: TRUE | B6: TRUE | C6: FALSE | D6: FALSE | E6: FALSE | F6: TRUE | G6: FALSE | H6: TRUE
A7: TRUE | B7: FALSE | C7: FALSE | D7: FALSE | E7: FALSE | F7: TRUE | G7: TRUE | H7: TRUE
A8: FALSE | B8: TRUE | C8: TRUE | D8: FALSE | E8: TRUE | F8: TRUE | G8: TRUE | H8: FALSE
I9: =COUNTIF(S19:Z26,TRUE)=1 -> FALSE | R9: =COUNTIF(S19:Z26,TRUE) -> 0
J10: =IF($I$9,A1,J10) -> TRUE | K10: =IF($I$9,B1,K10) -> FALSE | L10: =IF($I$9,C1,L10) -> TRUE | M10: =IF($I$9,D1,M10) -> TRUE | N10: =IF($I$9,E1,N10) -> FALSE | O10: =IF($I$9,F1,O10) -> TRUE | P10: =IF($I$9,G1,P10) -> TRUE | Q10: =IF($I$9,H1,Q10) -> FALSE
J11: =IF($I$9,A2,J11) -> TRUE | K11: =IF($I$9,B2,K11) -> FALSE | L11: =IF($I$9,C2,L11) -> FALSE | M11: =IF($I$9,D2,M11) -> TRUE | N11: =IF($I$9,E2,N11) -> FALSE | O11: =IF($I$9,F2,O11) -> FALSE | P11: =IF($I$9,G2,P11) -> FALSE | Q11: =IF($I$9,H2,Q11) -> TRUE
J12: =IF($I$9,A3,J12) -> TRUE | K12: =IF($I$9,B3,K12) -> FALSE | L12: =IF($I$9,C3,L12) -> TRUE | M12: =IF($I$9,D3,M12) -> FALSE | N12: =IF($I$9,E3,N12) -> TRUE | O12: =IF($I$9,F3,O12) -> TRUE | P12: =IF($I$9,G3,P12) -> FALSE | Q12: =IF($I$9,H3,Q12) -> TRUE
J13: =IF($I$9,A4,J13) -> TRUE | K13: =IF($I$9,B4,K13) -> FALSE | L13: =IF($I$9,C4,L13) -> FALSE | M13: =IF($I$9,D4,M13) -> TRUE | N13: =IF($I$9,E4,N13) -> FALSE | O13: =IF($I$9,F4,O13) -> TRUE | P13: =IF($I$9,G4,P13) -> TRUE | Q13: =IF($I$9,H4,Q13) -> TRUE
J14: =IF($I$9,A5,J14) -> TRUE | K14: =IF($I$9,B5,K14) -> FALSE | L14: =IF($I$9,C5,L14) -> FALSE | M14: =IF($I$9,D5,M14) -> TRUE | N14: =IF($I$9,E5,N14) -> FALSE | O14: =IF($I$9,F5,O14) -> FALSE | P14: =IF($I$9,G5,P14) -> FALSE | Q14: =IF($I$9,H5,Q14) -> TRUE
J15: =IF($I$9,A6,J15) -> TRUE | K15: =IF($I$9,B6,K15) -> TRUE | L15: =IF($I$9,C6,L15) -> FALSE | M15: =IF($I$9,D6,M15) -> FALSE | N15: =IF($I$9,E6,N15) -> FALSE | O15: =IF($I$9,F6,O15) -> TRUE | P15: =IF($I$9,G6,P15) -> FALSE | Q15: =IF($I$9,H6,Q15) -> TRUE
J16: =IF($I$9,A7,J16) -> TRUE | K16: =IF($I$9,B7,K16) -> FALSE | L16: =IF($I$9,C7,L16) -> FALSE | M16: =IF($I$9,D7,M16) -> FALSE | N16: =IF($I$9,E7,N16) -> FALSE | O16: =IF($I$9,F7,O16) -> TRUE | P16: =IF($I$9,G7,P16) -> TRUE | Q16: =IF($I$9,H7,Q16) -> TRUE
J17: =IF($I$9,A8,J17) -> FALSE | K17: =IF($I$9,B8,K17) -> TRUE | L17: =IF($I$9,C8,L17) -> TRUE | M17: =IF($I$9,D8,M17) -> FALSE | N17: =IF($I$9,E8,N17) -> TRUE | O17: =IF($I$9,F8,O17) -> TRUE | P17: =IF($I$9,G8,P17) -> TRUE | Q17: =IF($I$9,H8,Q17) -> FALSE
S19: =_xlfn.XOR(A1,J10) -> FALSE | T19: =_xlfn.XOR(B1,K10) -> FALSE | U19: =_xlfn.XOR(C1,L10) -> FALSE | V19: =_xlfn.XOR(D1,M10) -> FALSE | W19: =_xlfn.XOR(E1,N10) -> FALSE | X19: =_xlfn.XOR(F1,O10) -> FALSE | Y19: =_xlfn.XOR(G1,P10) -> FALSE | Z19: =_xlfn.XOR(H1,Q10) -> FALSE
S20: =_xlfn.XOR(A2,J11) -> FALSE | T20: =_xlfn.XOR(B2,K11) -> FALSE | U20: =_xlfn.XOR(C2,L11) -> FALSE | V20: =_xlfn.XOR(D2,M11) -> FALSE | W20: =_xlfn.XOR(E2,N11) -> FALSE | X20: =_xlfn.XOR(F2,O11) -> FALSE | Y20: =_xlfn.XOR(G2,P11) -> FALSE | Z20: =_xlfn.XOR(H2,Q11) -> FALSE
S21: =_xlfn.XOR(A3,J12) -> FALSE | T21: =_xlfn.XOR(B3,K12) -> FALSE | U21: =_xlfn.XOR(C3,L12) -> FALSE | V21: =_xlfn.XOR(D3,M12) -> FALSE | W21: =_xlfn.XOR(E3,N12) -> FALSE | X21: =_xlfn.XOR(F3,O12) -> FALSE | Y21: =_xlfn.XOR(G3,P12) -> FALSE | Z21: =_xlfn.XOR(H3,Q12) -> FALSE
S22: =_xlfn.XOR(A4,J13) -> FALSE | T22: =_xlfn.XOR(B4,K13) -> FALSE | U22: =_xlfn.XOR(C4,L13) -> FALSE | V22: =_xlfn.XOR(D4,M13) -> FALSE | W22: =_xlfn.XOR(E4,N13) -> FALSE | X22: =_xlfn.XOR(F4,O13) -> FALSE | Y22: =_xlfn.XOR(G4,P13) -> FALSE | Z22: =_xlfn.XOR(H4,Q13) -> FALSE
S23: =_xlfn.XOR(A5,J14) -> FALSE | T23: =_xlfn.XOR(B5,K14) -> FALSE | U23: =_xlfn.XOR(C5,L14) -> FALSE | V23: =_xlfn.XOR(D5,M14) -> FALSE | W23: =_xlfn.XOR(E5,N14) -> FALSE | X23: =_xlfn.XOR(F5,O14) -> FALSE | Y23: =_xlfn.XOR(G5,P14) -> FALSE | Z23: =_xlfn.XOR(H5,Q14) -> FALSE
S24: =_xlfn.XOR(A6,J15) -> FALSE | T24: =_xlfn.XOR(B6,K15) -> FALSE | U24: =_xlfn.XOR(C6,L15) -> FALSE | V24: =_xlfn.XOR(D6,M15) -> FALSE | W24: =_xlfn.XOR(E6,N15) -> FALSE | X24: =_xlfn.XOR(F6,O15) -> FALSE | Y24: =_xlfn.XOR(G6,P15) -> FALSE | Z24: =_xlfn.XOR(H6,Q15) -> FALSE
S25: =_xlfn.XOR(A7,J16) -> FALSE | T25: =_xlfn.XOR(B7,K16) -> FALSE | U25: =_xlfn.XOR(C7,L16) -> FALSE | V25: =_xlfn.XOR(D7,M16) -> FALSE | W25: =_xlfn.XOR(E7,N16) -> FALSE | X25: =_xlfn.XOR(F7,O16) -> FALSE | Y25: =_xlfn.XOR(G7,P16) -> FALSE | Z25: =_xlfn.XOR(H7,Q16) -> FALSE
S26: =_xlfn.XOR(A8,J17) -> FALSE | T26: =_xlfn.XOR(B8,K17) -> FALSE | U26: =_xlfn.XOR(C8,L17) -> FALSE | V26: =_xlfn.XOR(D8,M17) -> FALSE | W26: =_xlfn.XOR(E8,N17) -> FALSE | X26: =_xlfn.XOR(F8,O17) -> FALSE | Y26: =_xlfn.XOR(G8,P17) -> FALSE | Z26: =_xlfn.XOR(H8,Q17) -> FALSE
AJ27: =COUNTIF(AK37:AR44,TRUE) -> 0
AB28: =IF($I$9,AB28,A1) -> TRUE | AC28: =IF($I$9,AC28,B1) -> FALSE | AD28: =IF($I$9,AD28,C1) -> TRUE | AE28: =IF($I$9,AE28,D1) -> TRUE | AF28: =IF($I$9,AF28,E1) -> FALSE | AG28: =IF($I$9,AG28,F1) -> TRUE | AH28: =IF($I$9,AH28,G1) -> TRUE | AI28: =IF($I$9,AI28,H1) -> FALSE
AB29: =IF($I$9,AB29,A2) -> TRUE | AC29: =IF($I$9,AC29,B2) -> FALSE | AD29: =IF($I$9,AD29,C2) -> FALSE | AE29: =IF($I$9,AE29,D2) -> TRUE | AF29: =IF($I$9,AF29,E2) -> FALSE | AG29: =IF($I$9,AG29,F2) -> FALSE | AH29: =IF($I$9,AH29,G2) -> FALSE | AI29: =IF($I$9,AI29,H2) -> TRUE
AB30: =IF($I$9,AB30,A3) -> TRUE | AC30: =IF($I$9,AC30,B3) -> FALSE | AD30: =IF($I$9,AD30,C3) -> TRUE | AE30: =IF($I$9,AE30,D3) -> FALSE | AF30: =IF($I$9,AF30,E3) -> TRUE | AG30: =IF($I$9,AG30,F3) -> TRUE | AH30: =IF($I$9,AH30,G3) -> FALSE | AI30: =IF($I$9,AI30,H3) -> TRUE
AB31: =IF($I$9,AB31,A4) -> TRUE | AC31: =IF($I$9,AC31,B4) -> FALSE | AD31: =IF($I$9,AD31,C4) -> FALSE | AE31: =IF($I$9,AE31,D4) -> TRUE | AF31: =IF($I$9,AF31,E4) -> FALSE | AG31: =IF($I$9,AG31,F4) -> TRUE | AH31: =IF($I$9,AH31,G4) -> TRUE | AI31: =IF($I$9,AI31,H4) -> TRUE
AB32: =IF($I$9,AB32,A5) -> TRUE | AC32: =IF($I$9,AC32,B5) -> FALSE | AD32: =IF($I$9,AD32,C5) -> FALSE | AE32: =IF($I$9,AE32,D5) -> TRUE | AF32: =IF($I$9,AF32,E5) -> FALSE | AG32: =IF($I$9,AG32,F5) -> FALSE | AH32: =IF($I$9,AH32,G5) -> FALSE | AI32: =IF($I$9,AI32,H5) -> TRUE
AB33: =IF($I$9,AB33,A6) -> TRUE | AC33: =IF($I$9,AC33,B6) -> TRUE | AD33: =IF($I$9,AD33,C6) -> FALSE | AE33: =IF($I$9,AE33,D6) -> FALSE | AF33: =IF($I$9,AF33,E6) -> FALSE | AG33: =IF($I$9,AG33,F6) -> TRUE | AH33: =IF($I$9,AH33,G6) -> FALSE | AI33: =IF($I$9,AI33,H6) -> TRUE
AB34: =IF($I$9,AB34,A7) -> TRUE | AC34: =IF($I$9,AC34,B7) -> FALSE | AD34: =IF($I$9,AD34,C7) -> FALSE | AE34: =IF($I$9,AE34,D7) -> FALSE | AF34: =IF($I$9,AF34,E7) -> FALSE | AG34: =IF($I$9,AG34,F7) -> TRUE | AH34: =IF($I$9,AH34,G7) -> TRUE | AI34: =IF($I$9,AI34,H7) -> TRUE
AB35: =IF($I$9,AB35,A8) -> FALSE | AC35: =IF($I$9,AC35,B8) -> TRUE | AD35: =IF($I$9,AD35,C8) -> TRUE | AE35: =IF($I$9,AE35,D8) -> FALSE | AF35: =IF($I$9,AF35,E8) -> TRUE | AG35: =IF($I$9,AG35,F8) -> TRUE | AH35: =IF($I$9,AH35,G8) -> TRUE | AI35: =IF($I$9,AI35,H8) -> FALSE
AK37: =_xlfn.XOR(A1,AB28) -> FALSE | AL37: =_xlfn.XOR(B1,AC28) -> FALSE | AM37: =_xlfn.XOR(C1,AD28) -> FALSE | AN37: =_xlfn.XOR(D1,AE28) -> FALSE | AO37: =_xlfn.XOR(E1,AF28) -> FALSE | AP37: =_xlfn.XOR(F1,AG28) -> FALSE | AQ37: =_xlfn.XOR(G1,AH28) -> FALSE | AR37: =_xlfn.XOR(H1,AI28) -> FALSE
AK38: =_xlfn.XOR(A2,AB29) -> FALSE | AL38: =_xlfn.XOR(B2,AC29) -> FALSE | AM38: =_xlfn.XOR(C2,AD29) -> FALSE | AN38: =_xlfn.XOR(D2,AE29) -> FALSE | AO38: =_xlfn.XOR(E2,AF29) -> FALSE | AP38: =_xlfn.XOR(F2,AG29) -> FALSE | AQ38: =_xlfn.XOR(G2,AH29) -> FALSE | AR38: =_xlfn.XOR(H2,AI29) -> FALSE
AK39: =_xlfn.XOR(A3,AB30) -> FALSE | AL39: =_xlfn.XOR(B3,AC30) -> FALSE | AM39: =_xlfn.XOR(C3,AD30) -> FALSE | AN39: =_xlfn.XOR(D3,AE30) -> FALSE | AO39: =_xlfn.XOR(E3,AF30) -> FALSE | AP39: =_xlfn.XOR(F3,AG30) -> FALSE | AQ39: =_xlfn.XOR(G3,AH30) -> FALSE | AR39: =_xlfn.XOR(H3,AI30) -> FALSE
AK40: =_xlfn.XOR(A4,AB31) -> FALSE | AL40: =_xlfn.XOR(B4,AC31) -> FALSE | AM40: =_xlfn.XOR(C4,AD31) -> FALSE | AN40: =_xlfn.XOR(D4,AE31) -> FALSE | AO40: =_xlfn.XOR(E4,AF31) -> FALSE | AP40: =_xlfn.XOR(F4,AG31) -> FALSE | AQ40: =_xlfn.XOR(G4,AH31) -> FALSE | AR40: =_xlfn.XOR(H4,AI31) -> FALSE
AK41: =_xlfn.XOR(A5,AB32) -> FALSE | AL41: =_xlfn.XOR(B5,AC32) -> FALSE | AM41: =_xlfn.XOR(C5,AD32) -> FALSE | AN41: =_xlfn.XOR(D5,AE32) -> FALSE | AO41: =_xlfn.XOR(E5,AF32) -> FALSE | AP41: =_xlfn.XOR(F5,AG32) -> FALSE | AQ41: =_xlfn.XOR(G5,AH32) -> FALSE | AR41: =_xlfn.XOR(H5,AI32) -> FALSE
AK42: =_xlfn.XOR(A6,AB33) -> FALSE | AL42: =_xlfn.XOR(B6,AC33) -> FALSE | AM42: =_xlfn.XOR(C6,AD33) -> FALSE | AN42: =_xlfn.XOR(D6,AE33) -> FALSE | AO42: =_xlfn.XOR(E6,AF33) -> FALSE | AP42: =_xlfn.XOR(F6,AG33) -> FALSE | AQ42: =_xlfn.XOR(G6,AH33) -> FALSE | AR42: =_xlfn.XOR(H6,AI33) -> FALSE
...

Sheet inputsimplified
A1: ='input handling'!AT45 -> FALSE | B1: ='input handling'!AU45 -> FALSE | C1: ='input handling'!AV45 -> FALSE | D1: ='input handling'!AW45 -> FALSE | E1: ='input handling'!AX45 -> FALSE | F1: ='input handling'!AY45 -> FALSE | G1: ='input handling'!AZ45 -> FALSE | H1: ='input handling'!BA45 -> FALSE | I1: =livegame!R16 -> 1 | J1: white
A2: ='input handling'!AT46 -> FALSE | B2: ='input handling'!AU46 -> FALSE | C2: ='input handling'!AV46 -> FALSE | D2: ='input handling'!AW46 -> FALSE | E2: ='input handling'!AX46 -> FALSE | F2: ='input handling'!AY46 -> FALSE | G2: ='input handling'!AZ46 -> FALSE | H2: ='input handling'!BA46 -> FALSE | J2: N
A3: ='input handling'!AT47 -> FALSE | B3: ='input handling'!AU47 -> FALSE | C3: ='input handling'!AV47 -> FALSE | D3: ='input handling'!AW47 -> FALSE | E3: ='input handling'!AX47 -> FALSE | F3: ='input handling'!AY47 -> FALSE | G3: ='input handling'!AZ47 -> FALSE | H3: ='input handling'!BA47 -> FALSE | J3: C8
A4: ='input handling'!AT48 -> FALSE | B4: ='input handling'!AU48 -> FALSE | C4: ='input handling'!AV48 -> FALSE | D4: ='input handling'!AW48 -> FALSE | E4: ='input handling'!AX48 -> FALSE | F4: ='input handling'!AY48 -> FALSE | G4: ='input handling'!AZ48 -> FALSE | H4: ='input handling'!BA48 -> FALSE
A5: ='input handling'!AT49 -> FALSE | B5: ='input handling'!AU49 -> FALSE | C5: ='input handling'!AV49 -> FALSE | D5: ='input handling'!AW49 -> FALSE | E5: ='input handling'!AX49 -> FALSE | F5: ='input handling'!AY49 -> FALSE | G5: ='input handling'!AZ49 -> FALSE | H5: ='input handling'!BA49 -> FALSE
A6: ='input handling'!AT50 -> FALSE | B6: ='input handling'!AU50 -> FALSE | C6: ='input handling'!AV50 -> FALSE | D6: ='input handling'!AW50 -> FALSE | E6: ='input handling'!AX50 -> FALSE | F6: ='input handling'!AY50 -> FALSE | G6: ='input handling'!AZ50 -> FALSE | H6: ='input handling'!BA50 -> FALSE
A7: ='input handling'!AT51 -> FALSE | B7: ='input handling'!AU51 -> FALSE | C7: ='input handling'!AV51 -> FALSE | D7: ='input handling'!AW51 -> FALSE | E7: ='input handling'!AX51 -> FALSE | F7: ='input handling'!AY51 -> FALSE | G7: ='input handling'!AZ51 -> FALSE | H7: ='input handling'!BA51 -> FALSE
A8: ='input handling'!AT52 -> FALSE | B8: ='input handling'!AU52 -> FALSE | C8: ='input handling'!AV52 -> FALSE | D8: ='input handling'!AW52 -> FALSE | E8: ='input handling'!AX52 -> FALSE | F8: ='input handling'!AY52 -> FALSE | G8: ='input handling'!AZ52 -> FALSE | H8: ='input handling'!BA52 -> FALSE
I9: SelectedSpot | J9: {=_xlfn.LET(_xlpm.r,A1:H8, _xlpm.a,ADDRESS(_xlfn.SEQUENCE(ROWS(_xlpm.r)),_xlfn.SEQUENCE(,COLUMNS(_xlpm.r)),4), _xlfn.XLOOKUP(TRUE, _xlfn.TOCOL(_xlpm.r), _xlfn.TOCOL(_xlpm.a)))} -> #N/A
J10: SelectedVal | K10: {=INDIRECT("livegame!" & CHAR(CODE("A") + (CODE(UPPER(LEFT(J9,1))) - 65) + COLUMN($I$5) - 1) & (VALUE(MID(J9,2,99)) + ROW($I$5) - 1) )} -> #N/A
K11: isGamePieceYours: | L11: =AND(NOT(ISERR(SEARCH(I1, K10))),NOT(ISNA(SEARCH(I1, K10)))) -> FALSE
L12: playerTarget: | M12: =IF(OR(livegame!C1,NOT(livegame!S17="")),"",IF(L11,J9,M12))
M13: targetType: | N13: {=IFERROR(INDIRECT("livegame!" & CHAR(CODE("A") + (CODE(UPPER(LEFT(M12,1))) - 65) + COLUMN($I$5) - 1) & (VALUE(MID(M12,2,99)) + ROW($I$5) - 1) ),"")}
O14: Bishop
O15: {=_xlfn.LET(_xlpm.files,"ABCDEFGH",_xlpm.bf,FIND(UPPER(LEFT(M12,1)),_xlpm.files),_xlpm.br,--MID(M12,2,99),_xlpm.me,VALUE(RIGHT(N13,1)),_xlpm.board,piecetype!A1:H8,_xlpm.r,_xlfn.SEQUENCE(8,,1,1)+0*_xlfn.SEQUENCE(1,8,1,1),_xlpm.c,_xlfn.SEQUENCE(1,8,1,1)+0*_xlfn.SEQUENCE(8,,1,1),_xlpm.dr,_xlpm.r-_xlpm.br,_xlpm.dc,_xlpm.c-_xlpm.bf,_xlpm.dist,ABS(_xlpm.dr),_xlpm.self,(_xlpm.dr=0)*(_xlpm.dc=0),_xlpm.isDiag,ABS(_xlpm.dr)=ABS(_xlpm.dc),_xlpm.cand,_xlpm.isDiag*NOT(_xlpm.self),_xlpm.dir,IF(_xlpm.cand,IF(_xlpm.dr<0,IF(_xlpm.dc>0,1,2),IF(_xlpm.dc>0,3,4)),0),_xlpm.hasPiece,(_xlpm.board<>"")*NOT(_xlpm.self),_xlpm.block,_xlfn.MAP(_xlpm.dir,_xlfn.LAMBDA(_xlpm.d,IF(_xlpm.d=0,0,MIN(IF((_xlpm.dir=_xlpm.d)*_xlpm.hasPiece,_xlpm.dist,9))))),_xlpm.reachable,_xlpm.cand*IF(_xlpm.block=0,1,_xlpm.dist<=_xlpm.block),_xlpm.dest,IF(_xlpm.board="",0,VALUE(_xlpm.board)),_xlpm.legal,_xlpm.reachable*((_xlpm.dest=0)+((_xlpm.dest<>0)*(_xlpm.dest<>_xlpm.me))),_xlpm.legal=1)} -> #VALUE! | P15: #VALUE! | Q15: #VALUE! | R15: #VALUE! | S15: #VALUE! | T15: #VALUE! | U15: #VALUE! | V15: #VALUE!
M16: =_xlfn.LET(_xlpm.pos,$M$12,"pos="&_xlpm.pos&" row="&(CODE(UPPER(LEFT(_xlpm.pos,1)))-64)&" col="&VALUE(MID(_xlpm.pos,2,2))) -> #VALUE! | O16: #VALUE! | P16: #VALUE! | Q16: #VALUE! | R16: #VALUE! | S16: #VALUE! | T16: #VALUE! | U16: #VALUE! | V16: #VALUE!
O17: #VALUE! | P17: #VALUE! | Q17: #VALUE! | R17: #VALUE! | S17: #VALUE! | T17: #VALUE! | U17: #VALUE! | V17: #VALUE!
O18: #VALUE! | P18: #VALUE! | Q18: #VALUE! | R18: #VALUE! | S18: #VALUE! | T18: #VALUE! | U18: #VALUE! | V18: #VALUE!
O19: #VALUE! | P19: #VALUE! | Q19: #VALUE! | R19: #VALUE! | S19: #VALUE! | T19: #VALUE! | U19: #VALUE! | V19: #VALUE!
O20: #VALUE! | P20: #VALUE! | Q20: #VALUE! | R20: #VALUE! | S20: #VALUE! | T20: #VALUE! | U20: #VALUE! | V20: #VALUE!
O21: #VALUE! | P21: #VALUE! | Q21: #VALUE! | R21: #VALUE! | S21: #VALUE! | T21: #VALUE! | U21: #VALUE! | V21: #VALUE!
O22: #VALUE! | P22: #VALUE! | Q22: #VALUE! | R22: #VALUE! | S22: #VALUE! | T22: #VALUE! | U22: #VALUE! | V22: #VALUE!
O25: Rook
O26: {=_xlfn.LET(_xlpm.files,"ABCDEFGH",_xlpm.bf,FIND(UPPER(LEFT(M12,1)),_xlpm.files),_xlpm.br,--MID(M12,2,99),_xlpm.me,VALUE(RIGHT(N13,1)),_xlpm.board,piecetype!A1:H8,_xlpm.r,_xlfn.SEQUENCE(8,,1,1)+0*_xlfn.SEQUENCE(1,8,1,1),_xlpm.c,_xlfn.SEQUENCE(1,8,1,1)+0*_xlfn.SEQUENCE(8,,1,1),_xlpm.dr,_xlpm.r-_xlpm.br,_xlpm.dc,_xlpm.c-_xlpm.bf,_xlpm.dist,ABS(_xlpm.dr)+ABS(_xlpm.dc),_xlpm.self,(_xlpm.dr=0)*(_xlpm.dc=0),_xlpm.isLine,((_xlpm.dr=0)+(_xlpm.dc=0))*NOT(_xlpm.self),_xlpm.cand,_xlpm.isLine,_xlpm.dir,IF(_xlpm.cand,IF(_xlpm.dr=0,IF(_xlpm.dc>0,1,2),IF(_xlpm.dr>0,3,4)),0),_xlpm.hasPiece,(_xlpm.board<>"")*NOT(_xlpm.self),_xlpm.block,_xlfn.MAP(_xlpm.dir,_xlfn.LAMBDA(_xlpm.d,IF(_xlpm.d=0,0,MIN(IF((_xlpm.dir=_xlpm.d)*_xlpm.hasPiece,_xlpm.dist,9))))),_xlpm.reachable,_xlpm.cand*IF(_xlpm.block=0,1,_xlpm.dist<=_xlpm.block),_xlpm.dest,IF(_xlpm.board="",0,VALUE(_xlpm.board)),_xlpm.legal,_xlpm.reachable*((_xlpm.dest=0)+((_xlpm.dest<>0)*(_xlpm.dest<>_xlpm.me))),_xlpm.legal=1)} -> #VALUE! | P26: #VALUE! | Q26: #VALUE! | R26: #VALUE! | S26: #VALUE! | T26: #VALUE! | U26: #VALUE! | V26: #VALUE!
O27: #VALUE! | P27: #VALUE! | Q27: #VALUE! | R27: #VALUE! | S27: #VALUE! | T27: #VALUE! | U27: #VALUE! | V27: #VALUE!
O28: #VALUE! | P28: #VALUE! | Q28: #VALUE! | R28: #VALUE! | S28: #VALUE! | T28: #VALUE! | U28: #VALUE! | V28: #VALUE!
O29: #VALUE! | P29: #VALUE! | Q29: #VALUE! | R29: #VALUE! | S29: #VALUE! | T29: #VALUE! | U29: #VALUE! | V29: #VALUE!
O30: #VALUE! | P30: #VALUE! | Q30: #VALUE! | R30: #VALUE! | S30: #VALUE! | T30: #VALUE! | U30: #VALUE! | V30: #VALUE!
O31: #VALUE! | P31: #VALUE! | Q31: #VALUE! | R31: #VALUE! | S31: #VALUE! | T31: #VALUE! | U31: #VALUE! | V31: #VALUE!
O32: #VALUE! | P32: #VALUE! | Q32: #VALUE! | R32: #VALUE! | S32: #VALUE! | T32: #VALUE! | U32: #VALUE! | V32: #VALUE!
O33: #VALUE! | P33: #VALUE! | Q33: #VALUE! | R33: #VALUE! | S33: #VALUE! | T33: #VALUE! | U33: #VALUE! | V33: #VALUE!
O36: Queen
O37: {=_xlfn.LET(_xlpm.files,"ABCDEFGH",_xlpm.bf,FIND(UPPER(LEFT(M12,1)),_xlpm.files),_xlpm.br,--MID(M12,2,99),_xlpm.me,VALUE(RIGHT(N13,1)),_xlpm.board,piecetype!A1:H8,_xlpm.r,_xlfn.SEQUENCE(8,,1,1)+0*_xlfn.SEQUENCE(1,8,1,1),_xlpm.c,_xlfn.SEQUENCE(1,8,1,1)+0*_xlfn.SEQUENCE(8,,1,1),_xlpm.dr,_xlpm.r-_xlpm.br,_xlpm.dc,_xlpm.c-_xlpm.bf,_xlpm.dist,ABS(_xlpm.dr)+ABS(_xlpm.dc),_xlpm.self,(_xlpm.dr=0)*(_xlpm.dc=0), _xlpm.isLine,((_xlpm.dr=0)+(_xlpm.dc=0))*NOT(_xlpm.self), _xlpm.dirR,IF(_xlpm.isLine,IF(_xlpm.dr=0,IF(_xlpm.dc>0,1,2),IF(_xlpm.dr>0,3,4)),0), _xlpm.blockR,_xlfn.MAP(_xlpm.dirR,_xlfn.LAMBDA(_xlpm.d,IF(_xlpm.d=0,0,MIN(IF((_xlpm.dirR=_xlpm.d)*(_xlpm.board<>""),ABS(_xlpm.dr)+ABS(_xlpm.dc),9))))), _xlpm.reachR,_xlpm.isLine*IF(_xlpm.blockR=0,1,(ABS(_xlpm.dr)+ABS(_xlpm.dc))<=_xlpm.blockR), _xlpm.isDiag,(ABS(_xlpm.dr)=ABS(_xlpm.dc))*NOT(_xlpm.self), _xlpm.dirB,IF(_xlpm.isDiag,IF(_xlpm.dr<0,IF(_xlpm.dc>0,5,6),IF(_xlpm.dc>0,7,8)),0), _xlpm.blockB,_xlfn.MAP(_xlpm.dirB,_xlfn.LAMBDA(_xlpm.d,IF(_xlpm.d=0,0,MIN(IF((_xlpm.dirB=_xlpm.d)*(_xlpm.board<>""),ABS(_xlpm.dr),9))))), _xlpm.reachB,_xlpm.isDiag*IF(_xlpm.blockB=0,1,ABS(_xlpm.dr)<=_xlpm.blockB), _xlpm.reachable,_xlpm.reachR+_xlpm.reachB, _xlpm.dest,IF(_xlpm.board="",0,VALUE(_xlpm.board)), _xlpm.legal,_xlpm.reachable*((_xlpm.dest=0)+((_xlpm.dest<>0)*(_xlpm.dest<>_xlpm.me))), _xlpm.legal=1)} -> #VALUE! | P37: #VALUE! | Q37: #VALUE! | R37: #VALUE! | S37: #VALUE! | T37: #VALUE! | U37: #VALUE! | V37: #VALUE!
O38: #VALUE! | P38: #VALUE! | Q38: #VALUE! | R38: #VALUE! | S38: #VALUE! | T38: #VALUE! | U38: #VALUE! | V38: #VALUE!
O39: #VALUE! | P39: #VALUE! | Q39: #VALUE! | R39: #VALUE! | S39: #VALUE! | T39: #VALUE! | U39: #VALUE! | V39: #VALUE!
O40: #VALUE! | P40: #VALUE! | Q40: #VALUE! | R40: #VALUE! | S40: #VALUE! | T40: #VALUE! | U40: #VALUE! | V40: #VALUE!
O41: #VALUE! | P41: #VALUE! | Q41: #VALUE! | R41: #VALUE! | S41: #VALUE! | T41: #VALUE! | U41: #VALUE! | V41: #VALUE!
O42: #VALUE! | P42: #VALUE! | Q42: #VALUE! | R42: #VALUE! | S42: #VALUE! | T42: #VALUE! | U42: #VALUE! | V42: #VALUE!
O43: #VALUE! | P43: #VALUE! | Q43: #VALUE! | R43: #VALUE! | S43: #VALUE! | T43: #VALUE! | U43: #VALUE! | V43: #VALUE!
O44: #VALUE! | P44: #VALUE! | Q44: #VALUE! | R44: #VALUE! | S44: #VALUE! | T44: #VALUE! | U44: #VALUE! | V44: #VALUE!
...

Sheet livegame
B1: =IF(R16=1,"white","black") -> white | C1: =Sheet1!K2 -> TRUE | U1: =IF($C$1,0,IF($B$4=TRUE,U1+1,U1)) -> 0
A2: {=IF(Engine!$N$6,_xlfn.VSTACK(_xlfn.HSTACK("target pos:","","from pos:",""),_xlfn.HSTACK(Engine!$N$4,"can move:",Engine!$N$3,"type:"),_xlfn.HSTACK("",AND(Engine!$N$3<>"",Engine!$N$4<>"",Engine!$N$5<>""),"",Engine!$N$5)),inputsimplified!AG108:AJ110)} -> target pos: | B2: 0 | C2: from pos: | D2: 0
A3: #N/A | B3: can move: | D3: type:
A4: 0 | B4: FALSE | C4: 0
